<?xml version="1.0"?>
<robot name="printer3D">

  <material name="blue">
      <color rgba="0 0 0.8 1"/>
    </material>

  <material name="green">
      <color rgba="0 0.8 0 1"/>
    </material>    
    
  <link name="base_link">
    <visual>
      <origin xyz="0 0 0" rpy="-1.57075 0 0" />
        <geometry>
          <mesh filename="package://move_printer/urdf/printer.dae"/>
        </geometry>
    </visual>
  </link>

  <link name="world">
  </link>
  
  <link name="link_x">
  </link>
  <link name="link_y">
  </link>
  
  <link name="extruder_link">
    <visual>
      <origin xyz="0 0 0.35" rpy="0 0 0" />
        <geometry>
          <cylinder length="0.05" radius="0.01"/>
        </geometry>
        <material name="blue"/>
    </visual>
  </link>

  <link name="plateau">
    <visual>
      <origin xyz="0 0 0.025" rpy="0 0 0" />
        <geometry>
          <box size="0.25 0.25 0.01"/>
	  </geometry>
        <material name="green"/>
    </visual>
  </link>  
  
  <joint name="world_to_base" type="fixed">
    <parent link="world"/>
    <child link="base_link"/>
  </joint>
  
  <joint name="base_to_x" type="prismatic">
    <axis xyz="1 0 0"/>
    <parent link="base_link"/>
    <child link="link_x"/>
    <limit effort="1000.0" lower="-0.125" upper="0.125" velocity="0.1"/>
  </joint>

  <joint name="link_x_to_y" type="prismatic">
    <axis xyz="0 1 0"/>
    <parent link="link_x"/>
    <child link="link_y"/>
    <limit effort="1000.0" lower="-0.125" upper="0.125" velocity="0.1"/>
  </joint>
  
  <joint name="link_y_to_extruder" type="prismatic">
    <axis xyz="0 0 1"/>
    <parent link="link_y"/>
    <child link="extruder_link"/>
    <limit effort="1000.0" lower="-0.35" upper="0" velocity="0.1"/>
  </joint>
 
  
  <joint name="base_to_plateau" type="fixed">
    <axis xyz="0 0 1"/>
    <parent link="base_link"/>
    <child link="plateau"/>
  </joint>
  
</robot>
